2017-10-13 00:03:10 WARNING (MainThread) [homeassistant.setup] Setup of sensor is taking over 10 seconds.
2017-10-13 00:03:14 WARNING (MainThread) [homeassistant.setup] Setup of cover is taking over 10 seconds.
2017-10-13 00:03:40 WARNING (MainThread) [homeassistant.setup] Setup of tts is taking over 10 seconds.
2017-10-13 00:04:22 WARNING (MainThread) [homeassistant.setup] Setup of wink is taking over 10 seconds.
2017-10-13 00:04:56 WARNING (MainThread) [homeassistant.setup] Setup of climate is taking over 10 seconds.
2017-10-13 00:04:58 WARNING (MainThread) [homeassistant.setup] Setup of light is taking over 10 seconds.
2017-10-13 00:04:58 WARNING (MainThread) [homeassistant.setup] Setup of lock is taking over 10 seconds.
2017-10-13 00:04:59 WARNING (MainThread) [homeassistant.components.binary_sensor] Setup of platform wink is taking over 10 seconds.
2017-10-13 00:05:00 WARNING (MainThread) [homeassistant.setup] Setup of camera is taking over 10 seconds.
2017-10-13 00:05:00 WARNING (MainThread) [homeassistant.components.scene] Setup of platform wink is taking over 10 seconds.
2017-10-13 00:05:00 WARNING (MainThread) [homeassistant.components.binary_sensor] Setup of platform nest is taking over 10 seconds.
2017-10-13 00:05:02 WARNING (MainThread) [homeassistant.components.switch] Setup of platform wink is taking over 10 seconds.
2017-10-13 00:05:04 WARNING (MainThread) [homeassistant.components.alarm_control_panel] Setup of platform wink is taking over 10 seconds.
2017-10-13 00:06:25 WARNING (SyncWorker_2) [netdisco.ssdp] Error fetching description at https://192.168.1.17:8888
2017-10-13 00:35:07 WARNING (MainThread) [homeassistant.components.http.ban] Login attempt or request with invalid authentication from 192.168.1.13
2017-10-13 01:09:52 WARNING (MainThread) [homeassistant.helpers.entity] Update of sensor.owm_condition is taking over 10 seconds
2017-10-13 01:10:13 WARNING (MainThread) [homeassistant.components.sensor] Updating openweathermap sensor took longer than the scheduled update interval 0:00:30
2017-10-13 04:11:40 WARNING (MainThread) [homeassistant.helpers.entity] Update of cover.garage_door_opener is taking over 10 seconds
2017-10-13 08:03:34 ERROR (MainThread) [homeassistant.core] Timer got out of sync. Resetting
2017-10-13 08:39:59 ERROR (MainThread) [homeassistant.core] Error doing job: Fatal error on transport TCPTransport (error status in uv_stream_t.read callback)
OSError: [Errno 113] Host is unreachable
2017-10-13 08:40:12 ERROR (MainThread) [homeassistant.core] Timer got out of sync. Resetting
2017-10-13 08:41:42 WARNING (MainThread) [homeassistant.helpers.entity] Update of cover.garage_door_opener is taking over 10 seconds
2017-10-13 08:41:48 WARNING (MainThread) [homeassistant.components.cover] Updating myq cover took longer than the scheduled update interval 0:00:15
2017-10-13 13:20:31 ERROR (MainThread) [homeassistant.core] Timer got out of sync. Resetting
2017-10-13 15:57:47 WARNING (MainThread) [homeassistant.helpers.entity] Update of cover.garage_door_opener is taking over 10 seconds
2017-10-13 15:57:53 WARNING (MainThread) [homeassistant.components.cover] Updating myq cover took longer than the scheduled update interval 0:00:15
2017-10-13 15:58:09 WARNING (MainThread) [homeassistant.components.cover] Updating myq cover took longer than the scheduled update interval 0:00:15
2017-10-13 15:58:25 WARNING (MainThread) [homeassistant.components.cover] Updating myq cover took longer than the scheduled update interval 0:00:15
2017-10-13 16:41:32 WARNING (MainThread) [homeassistant.components.media_player] Setup of platform cast is taking over 10 seconds.
2017-10-13 16:45:23 ERROR (MainThread) [homeassistant.core] Timer got out of sync. Resetting
2017-10-13 17:37:01 WARNING (MainThread) [homeassistant.helpers.entity] Update of cover.garage_door_opener is taking over 10 seconds
2017-10-13 17:37:07 WARNING (MainThread) [homeassistant.components.cover] Updating myq cover took longer than the scheduled update interval 0:00:15
2017-10-13 18:15:37 ERROR (MainThread) [homeassistant.helpers.entity] Update for cover.garage_door_opener fails
Traceback (most recent call last):
  File "/usr/lib/python3.6/site-packages/requests/packages/urllib3/connection.py", line 141, in _new_conn
    (self.host, self.port), self.timeout, **extra_kw)
  File "/usr/lib/python3.6/site-packages/requests/packages/urllib3/util/connection.py", line 60, in create_connection
    for res in socket.getaddrinfo(host, port, family, socket.SOCK_STREAM):
  File "/usr/lib/python3.6/socket.py", line 743, in getaddrinfo
    for res in _socket.getaddrinfo(host, port, family, type, proto, flags):
socket.gaierror: [Errno -3] Try again

During handling of the above exception, another exception occurred:

Traceback (most recent call last):
  File "/usr/lib/python3.6/site-packages/requests/packages/urllib3/connectionpool.py", line 600, in urlopen
    chunked=chunked)
  File "/usr/lib/python3.6/site-packages/requests/packages/urllib3/connectionpool.py", line 345, in _make_request
    self._validate_conn(conn)
  File "/usr/lib/python3.6/site-packages/requests/packages/urllib3/connectionpool.py", line 844, in _validate_conn
    conn.connect()
  File "/usr/lib/python3.6/site-packages/requests/packages/urllib3/connection.py", line 284, in connect
    conn = self._new_conn()
  File "/usr/lib/python3.6/site-packages/requests/packages/urllib3/connection.py", line 150, in _new_conn
    self, "Failed to establish a new connection: %s" % e)
requests.packages.urllib3.exceptions.NewConnectionError: <requests.packages.urllib3.connection.VerifiedHTTPSConnection object at 0xb3e96050>: Failed to establish a new connection: [Errno -3] Try again

During handling of the above exception, another exception occurred:

Traceback (most recent call last):
  File "/usr/lib/python3.6/site-packages/requests/adapters.py", line 438, in send
    timeout=timeout
  File "/usr/lib/python3.6/site-packages/requests/packages/urllib3/connectionpool.py", line 649, in urlopen
    _stacktrace=sys.exc_info()[2])
  File "/usr/lib/python3.6/site-packages/requests/packages/urllib3/util/retry.py", line 388, in increment
    raise MaxRetryError(_pool, url, error or ResponseError(cause))
requests.packages.urllib3.exceptions.MaxRetryError: HTTPSConnectionPool(host='myqexternal.myqdevice.com', port=443): Max retries exceeded with url: /api/v4/UserDeviceDetails/Get (Caused by NewConnectionError('<requests.packages.urllib3.connection.VerifiedHTTPSConnection object at 0xb3e96050>: Failed to establish a new connection: [Errno -3] Try again',))

During handling of the above exception, another exception occurred:

Traceback (most recent call last):
  File "/usr/lib/python3.6/site-packages/homeassistant/helpers/entity.py", line 215, in async_update_ha_state
    yield from self.hass.async_add_job(self.update)
  File "/usr/lib/python3.6/asyncio/futures.py", line 331, in __iter__
    yield self  # This tells Task to wait for completion.
  File "/usr/lib/python3.6/asyncio/tasks.py", line 244, in _wakeup
    future.result()
  File "/usr/lib/python3.6/asyncio/futures.py", line 244, in result
    raise self._exception
  File "/usr/lib/python3.6/concurrent/futures/thread.py", line 55, in run
    result = self.fn(*self.args, **self.kwargs)
  File "/usr/lib/python3.6/site-packages/homeassistant/components/cover/myq.py", line 97, in update
    self._status = self.myq.get_status(self.device_id)
  File "/usr/lib/python3.6/site-packages/pymyq/__init__.py", line 153, in get_status
    devices = self.get_devices()
  File "/usr/lib/python3.6/site-packages/pymyq/__init__.py", line 118, in get_devices
    'User-Agent': self.USERAGENT
  File "/usr/lib/python3.6/site-packages/requests/api.py", line 72, in get
    return request('get', url, params=params, **kwargs)
  File "/usr/lib/python3.6/site-packages/requests/api.py", line 58, in request
    return session.request(method=method, url=url, **kwargs)
  File "/usr/lib/python3.6/site-packages/requests/sessions.py", line 518, in request
    resp = self.send(prep, **send_kwargs)
  File "/usr/lib/python3.6/site-packages/requests/sessions.py", line 639, in send
    r = adapter.send(request, **kwargs)
  File "/usr/lib/python3.6/site-packages/requests/adapters.py", line 502, in send
    raise ConnectionError(e, request=request)
requests.exceptions.ConnectionError: HTTPSConnectionPool(host='myqexternal.myqdevice.com', port=443): Max retries exceeded with url: /api/v4/UserDeviceDetails/Get (Caused by NewConnectionError('<requests.packages.urllib3.connection.VerifiedHTTPSConnection object at 0xb3e96050>: Failed to establish a new connection: [Errno -3] Try again',))
2017-10-13 18:15:52 ERROR (MainThread) [homeassistant.helpers.entity] Update for cover.garage_door_opener fails
Traceback (most recent call last):
  File "/usr/lib/python3.6/site-packages/requests/packages/urllib3/connection.py", line 141, in _new_conn
    (self.host, self.port), self.timeout, **extra_kw)
  File "/usr/lib/python3.6/site-packages/requests/packages/urllib3/util/connection.py", line 60, in create_connection
    for res in socket.getaddrinfo(host, port, family, socket.SOCK_STREAM):
  File "/usr/lib/python3.6/socket.py", line 743, in getaddrinfo
    for res in _socket.getaddrinfo(host, port, family, type, proto, flags):
socket.gaierror: [Errno -3] Try again

During handling of the above exception, another exception occurred:

Traceback (most recent call last):
  File "/usr/lib/python3.6/site-packages/requests/packages/urllib3/connectionpool.py", line 600, in urlopen
    chunked=chunked)
  File "/usr/lib/python3.6/site-packages/requests/packages/urllib3/connectionpool.py", line 345, in _make_request
    self._validate_conn(conn)
  File "/usr/lib/python3.6/site-packages/requests/packages/urllib3/connectionpool.py", line 844, in _validate_conn
    conn.connect()
  File "/usr/lib/python3.6/site-packages/requests/packages/urllib3/connection.py", line 284, in connect
    conn = self._new_conn()
  File "/usr/lib/python3.6/site-packages/requests/packages/urllib3/connection.py", line 150, in _new_conn
    self, "Failed to establish a new connection: %s" % e)
requests.packages.urllib3.exceptions.NewConnectionError: <requests.packages.urllib3.connection.VerifiedHTTPSConnection object at 0xb3d76df0>: Failed to establish a new connection: [Errno -3] Try again

During handling of the above exception, another exception occurred:

Traceback (most recent call last):
  File "/usr/lib/python3.6/site-packages/requests/adapters.py", line 438, in send
    timeout=timeout
  File "/usr/lib/python3.6/site-packages/requests/packages/urllib3/connectionpool.py", line 649, in urlopen
    _stacktrace=sys.exc_info()[2])
  File "/usr/lib/python3.6/site-packages/requests/packages/urllib3/util/retry.py", line 388, in increment
    raise MaxRetryError(_pool, url, error or ResponseError(cause))
requests.packages.urllib3.exceptions.MaxRetryError: HTTPSConnectionPool(host='myqexternal.myqdevice.com', port=443): Max retries exceeded with url: /api/v4/UserDeviceDetails/Get (Caused by NewConnectionError('<requests.packages.urllib3.connection.VerifiedHTTPSConnection object at 0xb3d76df0>: Failed to establish a new connection: [Errno -3] Try again',))

During handling of the above exception, another exception occurred:

Traceback (most recent call last):
  File "/usr/lib/python3.6/site-packages/homeassistant/helpers/entity.py", line 215, in async_update_ha_state
    yield from self.hass.async_add_job(self.update)
  File "/usr/lib/python3.6/asyncio/futures.py", line 331, in __iter__
    yield self  # This tells Task to wait for completion.
  File "/usr/lib/python3.6/asyncio/tasks.py", line 244, in _wakeup
    future.result()
  File "/usr/lib/python3.6/asyncio/futures.py", line 244, in result
    raise self._exception
  File "/usr/lib/python3.6/concurrent/futures/thread.py", line 55, in run
    result = self.fn(*self.args, **self.kwargs)
  File "/usr/lib/python3.6/site-packages/homeassistant/components/cover/myq.py", line 97, in update
    self._status = self.myq.get_status(self.device_id)
  File "/usr/lib/python3.6/site-packages/pymyq/__init__.py", line 153, in get_status
    devices = self.get_devices()
  File "/usr/lib/python3.6/site-packages/pymyq/__init__.py", line 118, in get_devices
    'User-Agent': self.USERAGENT
  File "/usr/lib/python3.6/site-packages/requests/api.py", line 72, in get
    return request('get', url, params=params, **kwargs)
  File "/usr/lib/python3.6/site-packages/requests/api.py", line 58, in request
    return session.request(method=method, url=url, **kwargs)
  File "/usr/lib/python3.6/site-packages/requests/sessions.py", line 518, in request
    resp = self.send(prep, **send_kwargs)
  File "/usr/lib/python3.6/site-packages/requests/sessions.py", line 639, in send
    r = adapter.send(request, **kwargs)
  File "/usr/lib/python3.6/site-packages/requests/adapters.py", line 502, in send
    raise ConnectionError(e, request=request)
requests.exceptions.ConnectionError: HTTPSConnectionPool(host='myqexternal.myqdevice.com', port=443): Max retries exceeded with url: /api/v4/UserDeviceDetails/Get (Caused by NewConnectionError('<requests.packages.urllib3.connection.VerifiedHTTPSConnection object at 0xb3d76df0>: Failed to establish a new connection: [Errno -3] Try again',))
2017-10-13 18:16:08 ERROR (MainThread) [homeassistant.helpers.entity] Update for cover.garage_door_opener fails
Traceback (most recent call last):
  File "/usr/lib/python3.6/site-packages/requests/packages/urllib3/connection.py", line 141, in _new_conn
    (self.host, self.port), self.timeout, **extra_kw)
  File "/usr/lib/python3.6/site-packages/requests/packages/urllib3/util/connection.py", line 60, in create_connection
    for res in socket.getaddrinfo(host, port, family, socket.SOCK_STREAM):
  File "/usr/lib/python3.6/socket.py", line 743, in getaddrinfo
    for res in _socket.getaddrinfo(host, port, family, type, proto, flags):
socket.gaierror: [Errno -3] Try again

During handling of the above exception, another exception occurred:

Traceback (most recent call last):
  File "/usr/lib/python3.6/site-packages/requests/packages/urllib3/connectionpool.py", line 600, in urlopen
    chunked=chunked)
  File "/usr/lib/python3.6/site-packages/requests/packages/urllib3/connectionpool.py", line 345, in _make_request
    self._validate_conn(conn)
  File "/usr/lib/python3.6/site-packages/requests/packages/urllib3/connectionpool.py", line 844, in _validate_conn
    conn.connect()
  File "/usr/lib/python3.6/site-packages/requests/packages/urllib3/connection.py", line 284, in connect
    conn = self._new_conn()
  File "/usr/lib/python3.6/site-packages/requests/packages/urllib3/connection.py", line 150, in _new_conn
    self, "Failed to establish a new connection: %s" % e)
requests.packages.urllib3.exceptions.NewConnectionError: <requests.packages.urllib3.connection.VerifiedHTTPSConnection object at 0xb3928730>: Failed to establish a new connection: [Errno -3] Try again

During handling of the above exception, another exception occurred:

Traceback (most recent call last):
  File "/usr/lib/python3.6/site-packages/requests/adapters.py", line 438, in send
    timeout=timeout
  File "/usr/lib/python3.6/site-packages/requests/packages/urllib3/connectionpool.py", line 649, in urlopen
    _stacktrace=sys.exc_info()[2])
  File "/usr/lib/python3.6/site-packages/requests/packages/urllib3/util/retry.py", line 388, in increment
    raise MaxRetryError(_pool, url, error or ResponseError(cause))
requests.packages.urllib3.exceptions.MaxRetryError: HTTPSConnectionPool(host='myqexternal.myqdevice.com', port=443): Max retries exceeded with url: /api/v4/UserDeviceDetails/Get (Caused by NewConnectionError('<requests.packages.urllib3.connection.VerifiedHTTPSConnection object at 0xb3928730>: Failed to establish a new connection: [Errno -3] Try again',))

During handling of the above exception, another exception occurred:

Traceback (most recent call last):
  File "/usr/lib/python3.6/site-packages/homeassistant/helpers/entity.py", line 215, in async_update_ha_state
    yield from self.hass.async_add_job(self.update)
  File "/usr/lib/python3.6/asyncio/futures.py", line 331, in __iter__
    yield self  # This tells Task to wait for completion.
  File "/usr/lib/python3.6/asyncio/tasks.py", line 244, in _wakeup
    future.result()
  File "/usr/lib/python3.6/asyncio/futures.py", line 244, in result
    raise self._exception
  File "/usr/lib/python3.6/concurrent/futures/thread.py", line 55, in run
    result = self.fn(*self.args, **self.kwargs)
  File "/usr/lib/python3.6/site-packages/homeassistant/components/cover/myq.py", line 97, in update
    self._status = self.myq.get_status(self.device_id)
  File "/usr/lib/python3.6/site-packages/pymyq/__init__.py", line 153, in get_status
    devices = self.get_devices()
  File "/usr/lib/python3.6/site-packages/pymyq/__init__.py", line 118, in get_devices
    'User-Agent': self.USERAGENT
  File "/usr/lib/python3.6/site-packages/requests/api.py", line 72, in get
    return request('get', url, params=params, **kwargs)
  File "/usr/lib/python3.6/site-packages/requests/api.py", line 58, in request
    return session.request(method=method, url=url, **kwargs)
  File "/usr/lib/python3.6/site-packages/requests/sessions.py", line 518, in request
    resp = self.send(prep, **send_kwargs)
  File "/usr/lib/python3.6/site-packages/requests/sessions.py", line 639, in send
    r = adapter.send(request, **kwargs)
  File "/usr/lib/python3.6/site-packages/requests/adapters.py", line 502, in send
    raise ConnectionError(e, request=request)
requests.exceptions.ConnectionError: HTTPSConnectionPool(host='myqexternal.myqdevice.com', port=443): Max retries exceeded with url: /api/v4/UserDeviceDetails/Get (Caused by NewConnectionError('<requests.packages.urllib3.connection.VerifiedHTTPSConnection object at 0xb3928730>: Failed to establish a new connection: [Errno -3] Try again',))
2017-10-13 18:16:24 ERROR (MainThread) [homeassistant.helpers.entity] Update for cover.garage_door_opener fails
Traceback (most recent call last):
  File "/usr/lib/python3.6/site-packages/requests/packages/urllib3/connection.py", line 141, in _new_conn
    (self.host, self.port), self.timeout, **extra_kw)
  File "/usr/lib/python3.6/site-packages/requests/packages/urllib3/util/connection.py", line 60, in create_connection
    for res in socket.getaddrinfo(host, port, family, socket.SOCK_STREAM):
  File "/usr/lib/python3.6/socket.py", line 743, in getaddrinfo
    for res in _socket.getaddrinfo(host, port, family, type, proto, flags):
socket.gaierror: [Errno -3] Try again

During handling of the above exception, another exception occurred:

Traceback (most recent call last):
  File "/usr/lib/python3.6/site-packages/requests/packages/urllib3/connectionpool.py", line 600, in urlopen
    chunked=chunked)
  File "/usr/lib/python3.6/site-packages/requests/packages/urllib3/connectionpool.py", line 345, in _make_request
    self._validate_conn(conn)
  File "/usr/lib/python3.6/site-packages/requests/packages/urllib3/connectionpool.py", line 844, in _validate_conn
    conn.connect()
  File "/usr/lib/python3.6/site-packages/requests/packages/urllib3/connection.py", line 284, in connect
    conn = self._new_conn()
  File "/usr/lib/python3.6/site-packages/requests/packages/urllib3/connection.py", line 150, in _new_conn
    self, "Failed to establish a new connection: %s" % e)
requests.packages.urllib3.exceptions.NewConnectionError: <requests.packages.urllib3.connection.VerifiedHTTPSConnection object at 0xb42015f0>: Failed to establish a new connection: [Errno -3] Try again

During handling of the above exception, another exception occurred:

Traceback (most recent call last):
  File "/usr/lib/python3.6/site-packages/requests/adapters.py", line 438, in send
    timeout=timeout
  File "/usr/lib/python3.6/site-packages/requests/packages/urllib3/connectionpool.py", line 649, in urlopen
    _stacktrace=sys.exc_info()[2])
  File "/usr/lib/python3.6/site-packages/requests/packages/urllib3/util/retry.py", line 388, in increment
    raise MaxRetryError(_pool, url, error or ResponseError(cause))
requests.packages.urllib3.exceptions.MaxRetryError: HTTPSConnectionPool(host='myqexternal.myqdevice.com', port=443): Max retries exceeded with url: /api/v4/UserDeviceDetails/Get (Caused by NewConnectionError('<requests.packages.urllib3.connection.VerifiedHTTPSConnection object at 0xb42015f0>: Failed to establish a new connection: [Errno -3] Try again',))

During handling of the above exception, another exception occurred:

Traceback (most recent call last):
  File "/usr/lib/python3.6/site-packages/homeassistant/helpers/entity.py", line 215, in async_update_ha_state
    yield from self.hass.async_add_job(self.update)
  File "/usr/lib/python3.6/asyncio/futures.py", line 331, in __iter__
    yield self  # This tells Task to wait for completion.
  File "/usr/lib/python3.6/asyncio/tasks.py", line 244, in _wakeup
    future.result()
  File "/usr/lib/python3.6/asyncio/futures.py", line 244, in result
    raise self._exception
  File "/usr/lib/python3.6/concurrent/futures/thread.py", line 55, in run
    result = self.fn(*self.args, **self.kwargs)
  File "/usr/lib/python3.6/site-packages/homeassistant/components/cover/myq.py", line 97, in update
    self._status = self.myq.get_status(self.device_id)
  File "/usr/lib/python3.6/site-packages/pymyq/__init__.py", line 153, in get_status
    devices = self.get_devices()
  File "/usr/lib/python3.6/site-packages/pymyq/__init__.py", line 118, in get_devices
    'User-Agent': self.USERAGENT
  File "/usr/lib/python3.6/site-packages/requests/api.py", line 72, in get
    return request('get', url, params=params, **kwargs)
  File "/usr/lib/python3.6/site-packages/requests/api.py", line 58, in request
    return session.request(method=method, url=url, **kwargs)
  File "/usr/lib/python3.6/site-packages/requests/sessions.py", line 518, in request
    resp = self.send(prep, **send_kwargs)
  File "/usr/lib/python3.6/site-packages/requests/sessions.py", line 639, in send
    r = adapter.send(request, **kwargs)
  File "/usr/lib/python3.6/site-packages/requests/adapters.py", line 502, in send
    raise ConnectionError(e, request=request)
requests.exceptions.ConnectionError: HTTPSConnectionPool(host='myqexternal.myqdevice.com', port=443): Max retries exceeded with url: /api/v4/UserDeviceDetails/Get (Caused by NewConnectionError('<requests.packages.urllib3.connection.VerifiedHTTPSConnection object at 0xb42015f0>: Failed to establish a new connection: [Errno -3] Try again',))
2017-10-13 18:22:05 WARNING (MainThread) [homeassistant.helpers.entity] Update of cover.garage_door_opener is taking over 10 seconds
2017-10-13 19:41:46 ERROR (MainThread) [homeassistant.core] Error doing job: Fatal error on transport TCPTransport (error status in uv_stream_t.read callback)
TimeoutError: [Errno 110] Operation timed out
2017-10-13 23:14:28 WARNING (MainThread) [homeassistant.helpers.entity] Update of cover.garage_door_opener is taking over 10 seconds
2017-10-14 00:48:46 WARNING (Thread-217) [pychromecast.socket_client] Heartbeat timeout, resetting connection
2017-10-14 00:49:16 ERROR (Thread-217) [pychromecast.socket_client] Failed to connect, retrying in 5.0s
2017-10-14 04:11:43 WARNING (MainThread) [homeassistant.helpers.entity] Update of cover.garage_door_opener is taking over 10 seconds
2017-10-14 04:11:49 WARNING (MainThread) [homeassistant.components.cover] Updating myq cover took longer than the scheduled update interval 0:00:15
2017-10-14 13:10:16 WARNING (MainThread) [homeassistant.helpers.entity] Update of cover.garage_door_opener is taking over 10 seconds
2017-10-14 13:10:22 WARNING (MainThread) [homeassistant.components.cover] Updating myq cover took longer than the scheduled update interval 0:00:15
2017-10-14 13:10:38 WARNING (MainThread) [homeassistant.components.cover] Updating myq cover took longer than the scheduled update interval 0:00:15
2017-10-14 13:10:54 WARNING (MainThread) [homeassistant.components.cover] Updating myq cover took longer than the scheduled update interval 0:00:15
2017-10-14 18:51:58 WARNING (MainThread) [homeassistant.helpers.entity] Update of cover.garage_door_opener is taking over 10 seconds
2017-10-14 23:49:47 WARNING (MainThread) [homeassistant.components.http.ban] Login attempt or request with invalid authentication from 172.30.33.2
2017-10-14 23:49:53 WARNING (MainThread) [homeassistant.components.http.ban] Login attempt or request with invalid authentication from 172.30.33.2
2017-10-14 23:49:58 WARNING (MainThread) [homeassistant.components.http.ban] Login attempt or request with invalid authentication from 172.30.33.2
2017-10-14 23:50:03 WARNING (MainThread) [homeassistant.components.http.ban] Login attempt or request with invalid authentication from 172.30.33.2
2017-10-14 23:50:08 WARNING (MainThread) [homeassistant.components.http.ban] Login attempt or request with invalid authentication from 172.30.33.2
2017-10-14 23:50:14 WARNING (MainThread) [homeassistant.components.http.ban] Login attempt or request with invalid authentication from 172.30.33.2
2017-10-14 23:50:19 WARNING (MainThread) [homeassistant.components.http.ban] Login attempt or request with invalid authentication from 172.30.33.2
2017-10-14 23:50:24 WARNING (MainThread) [homeassistant.components.http.ban] Login attempt or request with invalid authentication from 172.30.33.2
2017-10-14 23:50:29 WARNING (MainThread) [homeassistant.components.http.ban] Login attempt or request with invalid authentication from 172.30.33.2
2017-10-14 23:50:35 WARNING (MainThread) [homeassistant.components.http.ban] Login attempt or request with invalid authentication from 172.30.33.2
2017-10-14 23:50:40 WARNING (MainThread) [homeassistant.components.http.ban] Login attempt or request with invalid authentication from 172.30.33.2
2017-10-14 23:50:45 WARNING (MainThread) [homeassistant.components.http.ban] Login attempt or request with invalid authentication from 172.30.33.2
2017-10-14 23:50:50 WARNING (MainThread) [homeassistant.components.http.ban] Login attempt or request with invalid authentication from 172.30.33.2
2017-10-14 23:50:56 WARNING (MainThread) [homeassistant.components.http.ban] Login attempt or request with invalid authentication from 172.30.33.2
2017-10-14 23:51:01 WARNING (MainThread) [homeassistant.components.http.ban] Login attempt or request with invalid authentication from 172.30.33.2
2017-10-14 23:51:06 WARNING (MainThread) [homeassistant.components.http.ban] Login attempt or request with invalid authentication from 172.30.33.2
2017-10-14 23:51:11 WARNING (MainThread) [homeassistant.components.http.ban] Login attempt or request with invalid authentication from 172.30.33.2
2017-10-14 23:51:16 WARNING (MainThread) [homeassistant.components.http.ban] Login attempt or request with invalid authentication from 172.30.33.2
2017-10-14 23:51:22 WARNING (MainThread) [homeassistant.components.http.ban] Login attempt or request with invalid authentication from 172.30.33.2
2017-10-14 23:51:27 WARNING (MainThread) [homeassistant.components.http.ban] Login attempt or request with invalid authentication from 172.30.33.2
2017-10-14 23:51:32 WARNING (MainThread) [homeassistant.components.http.ban] Login attempt or request with invalid authentication from 172.30.33.2
2017-10-14 23:51:37 WARNING (MainThread) [homeassistant.components.http.ban] Login attempt or request with invalid authentication from 172.30.33.2
2017-10-14 23:51:42 WARNING (MainThread) [homeassistant.components.http.ban] Login attempt or request with invalid authentication from 172.30.33.2
2017-10-14 23:51:48 WARNING (MainThread) [homeassistant.components.http.ban] Login attempt or request with invalid authentication from 172.30.33.2
2017-10-14 23:51:53 WARNING (MainThread) [homeassistant.components.http.ban] Login attempt or request with invalid authentication from 172.30.33.2
2017-10-14 23:51:58 WARNING (MainThread) [homeassistant.components.http.ban] Login attempt or request with invalid authentication from 172.30.33.2
2017-10-14 23:52:03 WARNING (MainThread) [homeassistant.components.http.ban] Login attempt or request with invalid authentication from 172.30.33.2
2017-10-14 23:52:09 WARNING (MainThread) [homeassistant.components.http.ban] Login attempt or request with invalid authentication from 172.30.33.2
2017-10-14 23:52:14 WARNING (MainThread) [homeassistant.components.http.ban] Login attempt or request with invalid authentication from 172.30.33.2
2017-10-14 23:52:19 WARNING (MainThread) [homeassistant.components.http.ban] Login attempt or request with invalid authentication from 172.30.33.2
2017-10-14 23:52:24 WARNING (MainThread) [homeassistant.components.http.ban] Login attempt or request with invalid authentication from 172.30.33.2
2017-10-14 23:52:29 WARNING (MainThread) [homeassistant.components.http.ban] Login attempt or request with invalid authentication from 172.30.33.2
2017-10-14 23:52:35 WARNING (MainThread) [homeassistant.components.http.ban] Login attempt or request with invalid authentication from 172.30.33.2
2017-10-14 23:52:40 WARNING (MainThread) [homeassistant.components.http.ban] Login attempt or request with invalid authentication from 172.30.33.2
2017-10-14 23:52:45 WARNING (MainThread) [homeassistant.components.http.ban] Login attempt or request with invalid authentication from 172.30.33.2
2017-10-14 23:52:50 WARNING (MainThread) [homeassistant.components.http.ban] Login attempt or request with invalid authentication from 172.30.33.2
2017-10-14 23:52:55 WARNING (MainThread) [homeassistant.components.http.ban] Login attempt or request with invalid authentication from 172.30.33.2
2017-10-14 23:53:01 WARNING (MainThread) [homeassistant.components.http.ban] Login attempt or request with invalid authentication from 172.30.33.2
2017-10-14 23:53:06 WARNING (MainThread) [homeassistant.components.http.ban] Login attempt or request with invalid authentication from 172.30.33.2
2017-10-14 23:53:11 WARNING (MainThread) [homeassistant.components.http.ban] Login attempt or request with invalid authentication from 172.30.33.2
2017-10-14 23:53:16 WARNING (MainThread) [homeassistant.components.http.ban] Login attempt or request with invalid authentication from 172.30.33.2
2017-10-14 23:53:21 WARNING (MainThread) [homeassistant.components.http.ban] Login attempt or request with invalid authentication from 172.30.33.2
2017-10-14 23:53:27 WARNING (MainThread) [homeassistant.components.http.ban] Login attempt or request with invalid authentication from 172.30.33.2
2017-10-14 23:53:32 WARNING (MainThread) [homeassistant.components.http.ban] Login attempt or request with invalid authentication from 172.30.33.2
2017-10-14 23:53:37 WARNING (MainThread) [homeassistant.components.http.ban] Login attempt or request with invalid authentication from 172.30.33.2
2017-10-14 23:53:42 WARNING (MainThread) [homeassistant.components.http.ban] Login attempt or request with invalid authentication from 172.30.33.2
2017-10-14 23:53:48 WARNING (MainThread) [homeassistant.components.http.ban] Login attempt or request with invalid authentication from 172.30.33.2
2017-10-14 23:55:39 WARNING (Thread-217) [pychromecast.socket_client] Heartbeat timeout, resetting connection
2017-10-14 23:56:09 ERROR (Thread-217) [pychromecast.socket_client] Failed to connect, retrying in 5.0s
2017-10-15 00:15:45 ERROR (MainThread) [homeassistant.core] Error doing job: Fatal error on transport TCPTransport (error status in uv_stream_t.read callback)
OSError: [Errno 113] Host is unreachable
2017-10-15 00:16:04 ERROR (MainThread) [homeassistant.core] Error doing job: Fatal error on transport TCPTransport (error status in uv_stream_t.read callback)
OSError: [Errno 113] Host is unreachable
2017-10-15 02:30:18 ERROR (MainThread) [homeassistant.core] Error doing job: Fatal error on transport TCPTransport (error status in uv_stream_t.read callback)
TimeoutError: [Errno 110] Operation timed out
2017-10-15 04:10:56 WARNING (MainThread) [homeassistant.helpers.entity] Update of cover.garage_door_opener is taking over 10 seconds
2017-10-15 04:11:02 WARNING (MainThread) [homeassistant.components.cover] Updating myq cover took longer than the scheduled update interval 0:00:15
2017-10-15 17:06:05 ERROR (MainThread) [homeassistant.core] Timer got out of sync. Resetting
2017-10-15 19:22:42 ERROR (MainThread) [homeassistant.core] Error doing job: Fatal error on transport TCPTransport (error status in uv_stream_t.read callback)
TimeoutError: [Errno 110] Operation timed out
2017-10-15 23:42:27 WARNING (Thread-217) [pychromecast.socket_client] Heartbeat timeout, resetting connection
2017-10-15 23:42:57 ERROR (Thread-217) [pychromecast.socket_client] Failed to connect, retrying in 5.0s
2017-10-16 04:10:57 WARNING (MainThread) [homeassistant.helpers.entity] Update of cover.garage_door_opener is taking over 10 seconds
2017-10-16 04:11:03 WARNING (MainThread) [homeassistant.components.cover] Updating myq cover took longer than the scheduled update interval 0:00:15
2017-10-16 09:42:13 ERROR (MainThread) [homeassistant.core] Error doing job: Fatal error on transport TCPTransport (error status in uv_stream_t.read callback)
OSError: [Errno 113] Host is unreachable
2017-10-16 09:42:13 ERROR (MainThread) [homeassistant.core] Error doing job: Fatal error on transport TCPTransport (error status in uv_stream_t.read callback)
OSError: [Errno 113] Host is unreachable
2017-10-16 11:05:08 ERROR (MainThread) [homeassistant.core] Timer got out of sync. Resetting
2017-10-16 11:05:08 WARNING (MainThread) [homeassistant.helpers.entity] Update of cover.garage_door_opener is taking over 10 seconds
