2017-10-17 16:53:16 WARNING (MainThread) [homeassistant.setup] Setup of recorder is taking over 10 seconds.
2017-10-17 16:53:45 WARNING (MainThread) [homeassistant.setup] Setup of sensor is taking over 10 seconds.
2017-10-17 16:53:48 WARNING (MainThread) [homeassistant.setup] Setup of cover is taking over 10 seconds.
2017-10-17 16:54:01 WARNING (MainThread) [homeassistant.setup] Setup of tts is taking over 10 seconds.
2017-10-17 16:55:20 WARNING (MainThread) [homeassistant.setup] Setup of wink is taking over 10 seconds.
2017-10-17 16:55:53 WARNING (MainThread) [homeassistant.setup] Setup of light is taking over 10 seconds.
2017-10-17 16:55:53 WARNING (MainThread) [homeassistant.setup] Setup of lock is taking over 10 seconds.
2017-10-17 16:55:54 WARNING (MainThread) [homeassistant.components.binary_sensor] Setup of platform wink is taking over 10 seconds.
2017-10-17 16:57:01 ERROR (MainThread) [homeassistant.core] Timer got out of sync. Resetting
2017-10-17 16:57:10 WARNING (SyncWorker_0) [netdisco.ssdp] Error fetching description at https://192.168.1.17:8888
2017-10-17 18:47:57 WARNING (MainThread) [homeassistant.helpers.entity] Update of cover.garage_door_opener is taking over 10 seconds
2017-10-17 19:00:13 WARNING (MainThread) [homeassistant.helpers.entity] Update of cover.garage_door_opener is taking over 10 seconds
2017-10-17 19:31:08 WARNING (MainThread) [homeassistant.helpers.entity] Update of cover.garage_door_opener is taking over 10 seconds
2017-10-17 19:36:12 WARNING (MainThread) [homeassistant.helpers.entity] Update of cover.garage_door_opener is taking over 10 seconds
2017-10-17 19:41:00 WARNING (MainThread) [homeassistant.helpers.entity] Update of cover.garage_door_opener is taking over 10 seconds
2017-10-17 19:57:16 WARNING (MainThread) [homeassistant.helpers.entity] Update of cover.garage_door_opener is taking over 10 seconds
2017-10-17 19:57:22 WARNING (MainThread) [homeassistant.components.cover] Updating myq cover took longer than the scheduled update interval 0:00:15
2017-10-17 20:03:32 ERROR (SyncWorker_0) [pymyq] MyQ - API Error[get_devices] 503 Server Error: Service Unavailable for url: https://myqexternal.myqdevice.com/api/v4/UserDeviceDetails/Get
2017-10-17 20:03:32 ERROR (MainThread) [homeassistant.helpers.entity] Update for cover.garage_door_opener fails
Traceback (most recent call last):
  File "/usr/lib/python3.6/site-packages/homeassistant/helpers/entity.py", line 215, in async_update_ha_state
    yield from self.hass.async_add_job(self.update)
  File "/usr/lib/python3.6/asyncio/futures.py", line 331, in __iter__
    yield self  # This tells Task to wait for completion.
  File "/usr/lib/python3.6/asyncio/tasks.py", line 244, in _wakeup
    future.result()
  File "/usr/lib/python3.6/asyncio/futures.py", line 244, in result
    raise self._exception
  File "/usr/lib/python3.6/concurrent/futures/thread.py", line 55, in run
    result = self.fn(*self.args, **self.kwargs)
  File "/usr/lib/python3.6/site-packages/homeassistant/components/cover/myq.py", line 97, in update
    self._status = self.myq.get_status(self.device_id)
  File "/usr/lib/python3.6/site-packages/pymyq/__init__.py", line 155, in get_status
    for device in devices:
TypeError: 'bool' object is not iterable
2017-10-17 20:04:28 WARNING (MainThread) [homeassistant.helpers.entity] Update of cover.garage_door_opener is taking over 10 seconds
2017-10-17 20:04:34 WARNING (MainThread) [homeassistant.components.cover] Updating myq cover took longer than the scheduled update interval 0:00:15
2017-10-17 20:04:50 WARNING (MainThread) [homeassistant.components.cover] Updating myq cover took longer than the scheduled update interval 0:00:15
2017-10-17 22:17:13 WARNING (MainThread) [homeassistant.components.media_player] Setup of platform cast is taking over 10 seconds.
2017-10-18 00:13:16 ERROR (MainThread) [homeassistant.helpers.entity] Update for cover.garage_door_opener fails
Traceback (most recent call last):
  File "/usr/lib/python3.6/site-packages/requests/packages/urllib3/connection.py", line 141, in _new_conn
    (self.host, self.port), self.timeout, **extra_kw)
  File "/usr/lib/python3.6/site-packages/requests/packages/urllib3/util/connection.py", line 60, in create_connection
    for res in socket.getaddrinfo(host, port, family, socket.SOCK_STREAM):
  File "/usr/lib/python3.6/socket.py", line 743, in getaddrinfo
    for res in _socket.getaddrinfo(host, port, family, type, proto, flags):
socket.gaierror: [Errno -3] Try again

During handling of the above exception, another exception occurred:

Traceback (most recent call last):
  File "/usr/lib/python3.6/site-packages/requests/packages/urllib3/connectionpool.py", line 600, in urlopen
    chunked=chunked)
  File "/usr/lib/python3.6/site-packages/requests/packages/urllib3/connectionpool.py", line 345, in _make_request
    self._validate_conn(conn)
  File "/usr/lib/python3.6/site-packages/requests/packages/urllib3/connectionpool.py", line 844, in _validate_conn
    conn.connect()
  File "/usr/lib/python3.6/site-packages/requests/packages/urllib3/connection.py", line 284, in connect
    conn = self._new_conn()
  File "/usr/lib/python3.6/site-packages/requests/packages/urllib3/connection.py", line 150, in _new_conn
    self, "Failed to establish a new connection: %s" % e)
requests.packages.urllib3.exceptions.NewConnectionError: <requests.packages.urllib3.connection.VerifiedHTTPSConnection object at 0xb4161530>: Failed to establish a new connection: [Errno -3] Try again

During handling of the above exception, another exception occurred:

Traceback (most recent call last):
  File "/usr/lib/python3.6/site-packages/requests/adapters.py", line 438, in send
    timeout=timeout
  File "/usr/lib/python3.6/site-packages/requests/packages/urllib3/connectionpool.py", line 649, in urlopen
    _stacktrace=sys.exc_info()[2])
  File "/usr/lib/python3.6/site-packages/requests/packages/urllib3/util/retry.py", line 388, in increment
    raise MaxRetryError(_pool, url, error or ResponseError(cause))
requests.packages.urllib3.exceptions.MaxRetryError: HTTPSConnectionPool(host='myqexternal.myqdevice.com', port=443): Max retries exceeded with url: /api/v4/UserDeviceDetails/Get (Caused by NewConnectionError('<requests.packages.urllib3.connection.VerifiedHTTPSConnection object at 0xb4161530>: Failed to establish a new connection: [Errno -3] Try again',))

During handling of the above exception, another exception occurred:

Traceback (most recent call last):
  File "/usr/lib/python3.6/site-packages/homeassistant/helpers/entity.py", line 215, in async_update_ha_state
    yield from self.hass.async_add_job(self.update)
  File "/usr/lib/python3.6/asyncio/futures.py", line 331, in __iter__
    yield self  # This tells Task to wait for completion.
  File "/usr/lib/python3.6/asyncio/tasks.py", line 244, in _wakeup
    future.result()
  File "/usr/lib/python3.6/asyncio/futures.py", line 244, in result
    raise self._exception
  File "/usr/lib/python3.6/concurrent/futures/thread.py", line 55, in run
    result = self.fn(*self.args, **self.kwargs)
  File "/usr/lib/python3.6/site-packages/homeassistant/components/cover/myq.py", line 97, in update
    self._status = self.myq.get_status(self.device_id)
  File "/usr/lib/python3.6/site-packages/pymyq/__init__.py", line 153, in get_status
    devices = self.get_devices()
  File "/usr/lib/python3.6/site-packages/pymyq/__init__.py", line 118, in get_devices
    'User-Agent': self.USERAGENT
  File "/usr/lib/python3.6/site-packages/requests/api.py", line 72, in get
    return request('get', url, params=params, **kwargs)
  File "/usr/lib/python3.6/site-packages/requests/api.py", line 58, in request
    return session.request(method=method, url=url, **kwargs)
  File "/usr/lib/python3.6/site-packages/requests/sessions.py", line 518, in request
    resp = self.send(prep, **send_kwargs)
  File "/usr/lib/python3.6/site-packages/requests/sessions.py", line 639, in send
    r = adapter.send(request, **kwargs)
  File "/usr/lib/python3.6/site-packages/requests/adapters.py", line 502, in send
    raise ConnectionError(e, request=request)
requests.exceptions.ConnectionError: HTTPSConnectionPool(host='myqexternal.myqdevice.com', port=443): Max retries exceeded with url: /api/v4/UserDeviceDetails/Get (Caused by NewConnectionError('<requests.packages.urllib3.connection.VerifiedHTTPSConnection object at 0xb4161530>: Failed to establish a new connection: [Errno -3] Try again',))
2017-10-18 00:13:32 ERROR (MainThread) [homeassistant.helpers.entity] Update for cover.garage_door_opener fails
Traceback (most recent call last):
  File "/usr/lib/python3.6/site-packages/requests/packages/urllib3/connection.py", line 141, in _new_conn
    (self.host, self.port), self.timeout, **extra_kw)
  File "/usr/lib/python3.6/site-packages/requests/packages/urllib3/util/connection.py", line 60, in create_connection
    for res in socket.getaddrinfo(host, port, family, socket.SOCK_STREAM):
  File "/usr/lib/python3.6/socket.py", line 743, in getaddrinfo
    for res in _socket.getaddrinfo(host, port, family, type, proto, flags):
socket.gaierror: [Errno -3] Try again

During handling of the above exception, another exception occurred:

Traceback (most recent call last):
  File "/usr/lib/python3.6/site-packages/requests/packages/urllib3/connectionpool.py", line 600, in urlopen
    chunked=chunked)
  File "/usr/lib/python3.6/site-packages/requests/packages/urllib3/connectionpool.py", line 345, in _make_request
    self._validate_conn(conn)
  File "/usr/lib/python3.6/site-packages/requests/packages/urllib3/connectionpool.py", line 844, in _validate_conn
    conn.connect()
  File "/usr/lib/python3.6/site-packages/requests/packages/urllib3/connection.py", line 284, in connect
    conn = self._new_conn()
  File "/usr/lib/python3.6/site-packages/requests/packages/urllib3/connection.py", line 150, in _new_conn
    self, "Failed to establish a new connection: %s" % e)
requests.packages.urllib3.exceptions.NewConnectionError: <requests.packages.urllib3.connection.VerifiedHTTPSConnection object at 0xb5644890>: Failed to establish a new connection: [Errno -3] Try again

During handling of the above exception, another exception occurred:

Traceback (most recent call last):
  File "/usr/lib/python3.6/site-packages/requests/adapters.py", line 438, in send
    timeout=timeout
  File "/usr/lib/python3.6/site-packages/requests/packages/urllib3/connectionpool.py", line 649, in urlopen
    _stacktrace=sys.exc_info()[2])
  File "/usr/lib/python3.6/site-packages/requests/packages/urllib3/util/retry.py", line 388, in increment
    raise MaxRetryError(_pool, url, error or ResponseError(cause))
requests.packages.urllib3.exceptions.MaxRetryError: HTTPSConnectionPool(host='myqexternal.myqdevice.com', port=443): Max retries exceeded with url: /api/v4/UserDeviceDetails/Get (Caused by NewConnectionError('<requests.packages.urllib3.connection.VerifiedHTTPSConnection object at 0xb5644890>: Failed to establish a new connection: [Errno -3] Try again',))

During handling of the above exception, another exception occurred:

Traceback (most recent call last):
  File "/usr/lib/python3.6/site-packages/homeassistant/helpers/entity.py", line 215, in async_update_ha_state
    yield from self.hass.async_add_job(self.update)
  File "/usr/lib/python3.6/asyncio/futures.py", line 331, in __iter__
    yield self  # This tells Task to wait for completion.
  File "/usr/lib/python3.6/asyncio/tasks.py", line 244, in _wakeup
    future.result()
  File "/usr/lib/python3.6/asyncio/futures.py", line 244, in result
    raise self._exception
  File "/usr/lib/python3.6/concurrent/futures/thread.py", line 55, in run
    result = self.fn(*self.args, **self.kwargs)
  File "/usr/lib/python3.6/site-packages/homeassistant/components/cover/myq.py", line 97, in update
    self._status = self.myq.get_status(self.device_id)
  File "/usr/lib/python3.6/site-packages/pymyq/__init__.py", line 153, in get_status
    devices = self.get_devices()
  File "/usr/lib/python3.6/site-packages/pymyq/__init__.py", line 118, in get_devices
    'User-Agent': self.USERAGENT
  File "/usr/lib/python3.6/site-packages/requests/api.py", line 72, in get
    return request('get', url, params=params, **kwargs)
  File "/usr/lib/python3.6/site-packages/requests/api.py", line 58, in request
    return session.request(method=method, url=url, **kwargs)
  File "/usr/lib/python3.6/site-packages/requests/sessions.py", line 518, in request
    resp = self.send(prep, **send_kwargs)
  File "/usr/lib/python3.6/site-packages/requests/sessions.py", line 639, in send
    r = adapter.send(request, **kwargs)
  File "/usr/lib/python3.6/site-packages/requests/adapters.py", line 502, in send
    raise ConnectionError(e, request=request)
requests.exceptions.ConnectionError: HTTPSConnectionPool(host='myqexternal.myqdevice.com', port=443): Max retries exceeded with url: /api/v4/UserDeviceDetails/Get (Caused by NewConnectionError('<requests.packages.urllib3.connection.VerifiedHTTPSConnection object at 0xb5644890>: Failed to establish a new connection: [Errno -3] Try again',))
2017-10-18 00:13:48 ERROR (MainThread) [homeassistant.helpers.entity] Update for cover.garage_door_opener fails
Traceback (most recent call last):
  File "/usr/lib/python3.6/site-packages/requests/packages/urllib3/connection.py", line 141, in _new_conn
    (self.host, self.port), self.timeout, **extra_kw)
  File "/usr/lib/python3.6/site-packages/requests/packages/urllib3/util/connection.py", line 60, in create_connection
    for res in socket.getaddrinfo(host, port, family, socket.SOCK_STREAM):
  File "/usr/lib/python3.6/socket.py", line 743, in getaddrinfo
    for res in _socket.getaddrinfo(host, port, family, type, proto, flags):
socket.gaierror: [Errno -3] Try again

During handling of the above exception, another exception occurred:

Traceback (most recent call last):
  File "/usr/lib/python3.6/site-packages/requests/packages/urllib3/connectionpool.py", line 600, in urlopen
    chunked=chunked)
  File "/usr/lib/python3.6/site-packages/requests/packages/urllib3/connectionpool.py", line 345, in _make_request
    self._validate_conn(conn)
  File "/usr/lib/python3.6/site-packages/requests/packages/urllib3/connectionpool.py", line 844, in _validate_conn
    conn.connect()
  File "/usr/lib/python3.6/site-packages/requests/packages/urllib3/connection.py", line 284, in connect
    conn = self._new_conn()
  File "/usr/lib/python3.6/site-packages/requests/packages/urllib3/connection.py", line 150, in _new_conn
    self, "Failed to establish a new connection: %s" % e)
requests.packages.urllib3.exceptions.NewConnectionError: <requests.packages.urllib3.connection.VerifiedHTTPSConnection object at 0xb42ca9d0>: Failed to establish a new connection: [Errno -3] Try again

During handling of the above exception, another exception occurred:

Traceback (most recent call last):
  File "/usr/lib/python3.6/site-packages/requests/adapters.py", line 438, in send
    timeout=timeout
  File "/usr/lib/python3.6/site-packages/requests/packages/urllib3/connectionpool.py", line 649, in urlopen
    _stacktrace=sys.exc_info()[2])
  File "/usr/lib/python3.6/site-packages/requests/packages/urllib3/util/retry.py", line 388, in increment
    raise MaxRetryError(_pool, url, error or ResponseError(cause))
requests.packages.urllib3.exceptions.MaxRetryError: HTTPSConnectionPool(host='myqexternal.myqdevice.com', port=443): Max retries exceeded with url: /api/v4/UserDeviceDetails/Get (Caused by NewConnectionError('<requests.packages.urllib3.connection.VerifiedHTTPSConnection object at 0xb42ca9d0>: Failed to establish a new connection: [Errno -3] Try again',))

During handling of the above exception, another exception occurred:

Traceback (most recent call last):
  File "/usr/lib/python3.6/site-packages/homeassistant/helpers/entity.py", line 215, in async_update_ha_state
    yield from self.hass.async_add_job(self.update)
  File "/usr/lib/python3.6/asyncio/futures.py", line 331, in __iter__
    yield self  # This tells Task to wait for completion.
  File "/usr/lib/python3.6/asyncio/tasks.py", line 244, in _wakeup
    future.result()
  File "/usr/lib/python3.6/asyncio/futures.py", line 244, in result
    raise self._exception
  File "/usr/lib/python3.6/concurrent/futures/thread.py", line 55, in run
    result = self.fn(*self.args, **self.kwargs)
  File "/usr/lib/python3.6/site-packages/homeassistant/components/cover/myq.py", line 97, in update
    self._status = self.myq.get_status(self.device_id)
  File "/usr/lib/python3.6/site-packages/pymyq/__init__.py", line 153, in get_status
    devices = self.get_devices()
  File "/usr/lib/python3.6/site-packages/pymyq/__init__.py", line 118, in get_devices
    'User-Agent': self.USERAGENT
  File "/usr/lib/python3.6/site-packages/requests/api.py", line 72, in get
    return request('get', url, params=params, **kwargs)
  File "/usr/lib/python3.6/site-packages/requests/api.py", line 58, in request
    return session.request(method=method, url=url, **kwargs)
  File "/usr/lib/python3.6/site-packages/requests/sessions.py", line 518, in request
    resp = self.send(prep, **send_kwargs)
  File "/usr/lib/python3.6/site-packages/requests/sessions.py", line 639, in send
    r = adapter.send(request, **kwargs)
  File "/usr/lib/python3.6/site-packages/requests/adapters.py", line 502, in send
    raise ConnectionError(e, request=request)
requests.exceptions.ConnectionError: HTTPSConnectionPool(host='myqexternal.myqdevice.com', port=443): Max retries exceeded with url: /api/v4/UserDeviceDetails/Get (Caused by NewConnectionError('<requests.packages.urllib3.connection.VerifiedHTTPSConnection object at 0xb42ca9d0>: Failed to establish a new connection: [Errno -3] Try again',))
2017-10-18 00:40:08 WARNING (Thread-72) [pychromecast.socket_client] Heartbeat timeout, resetting connection
2017-10-18 00:40:26 ERROR (Thread-72) [pychromecast.socket_client] Failed to connect, retrying in 5.0s
2017-10-18 04:10:17 WARNING (MainThread) [homeassistant.helpers.entity] Update of cover.garage_door_opener is taking over 10 seconds
2017-10-18 04:10:23 WARNING (MainThread) [homeassistant.components.cover] Updating myq cover took longer than the scheduled update interval 0:00:15
2017-10-18 04:10:39 WARNING (MainThread) [homeassistant.components.cover] Updating myq cover took longer than the scheduled update interval 0:00:15
2017-10-18 04:10:55 WARNING (MainThread) [homeassistant.components.cover] Updating myq cover took longer than the scheduled update interval 0:00:15
2017-10-18 07:44:39 WARNING (MainThread) [homeassistant.helpers.entity] Update of cover.garage_door_opener is taking over 10 seconds
2017-10-18 09:02:50 ERROR (MainThread) [homeassistant.core] Error doing job: Fatal error on transport TCPTransport (error status in uv_stream_t.read callback)
OSError: [Errno 113] Host is unreachable
